Workbook
Name MONTH: 'Base Data'!$B$15
Name IND_YEAR_1: 'Base Data'!$E$8
Name YEAR_4: 'Base Data'!$B$11
Name IND_YEAR_6: 'Base Data'!$E$13
Name IND_YEAR_5: 'Base Data'!$E$12
Name YEAR_1: 'Base Data'!$B$8
Name IND_YEAR_2: 'Base Data'!$E$9
Name SP_EXCEL_LINK_7353616ca9ac4baea658f5be2f83c964: OVERVIEW!$B$8:$BT$82
Name YEAR_3: 'Base Data'!$B$10
Name COMP: 'Base Data'!$B$5
Name YEAR_2: 'Base Data'!$B$9
Name YEAR_6: 'Base Data'!$B$13
Name IND_YEAR_3: 'Base Data'!$E$10
Name SP_EXCEL_LINK_ffb73710684542a98aad81c21bf8ac33: #REF!
Name YEAR_5: 'Base Data'!$B$12
Name YEAR: 'Base Data'!$B$7
Name IND_YEAR_4: 'Base Data'!$E$11

Sheet OVERVIEW
B1: Comp | D1: =+COMP -> ZHY | E1: =+COMP -> ZHY | F1: =+COMP -> ZHY | G1: =+COMP -> ZHY | H1: =+COMP -> ZHY | I1: =+COMP -> ZHY | J1: =+COMP -> ZHY | K1: =+COMP -> ZHY | ... P1: =+COMP -> ZHY | R1: =+COMP -> ZHY | S1: =+COMP -> ZHY | T1: =+COMP -> ZHY | U1: =+COMP -> ZHY | V1: =+COMP -> ZHY | W1: =+COMP -> ZHY | X1: =+COMP -> ZHY | Y1: =+COMP -> ZHY | ... AD1: =+COMP -> ZHY | AF1: =+COMP -> ZHY | AG1: =+COMP -> ZHY | AH1: =+COMP -> ZHY | AI1: =+COMP -> ZHY | AJ1: =+COMP -> ZHY | AK1: =+COMP -> ZHY | AL1: =+COMP -> ZHY | AM1: =+COMP -> ZHY | ... AR1: =+COMP -> ZHY | AT1: =+COMP -> ZHY | AU1: =+COMP -> ZHY | AV1: =+COMP -> ZHY | AW1: =+COMP -> ZHY | AX1: =+COMP -> ZHY | AY1: =+COMP -> ZHY | AZ1: =+COMP -> ZHY | BA1: =+COMP -> ZHY | ... BF1: =+COMP -> ZHY | BH1: =+COMP -> ZHY | BI1: =+COMP -> ZHY | BJ1: =+COMP -> ZHY | BK1: =+COMP -> ZHY | BL1: =+COMP -> ZHY | BM1: =+COMP -> ZHY | BN1: =+COMP -> ZHY | BO1: =+COMP -> ZHY | ... BT1: =+COMP -> ZHY | BV1: =+COMP -> ZHY | BW1: =+COMP -> ZHY | BX1: =+COMP -> ZHY | BY1: =+COMP -> ZHY | BZ1: =+COMP -> ZHY | CA1: =+COMP -> ZHY | CB1: =+COMP -> ZHY | CC1: =+COMP -> ZHY | ... CH1: =+COMP -> ZHY
B2: YEAR | D2: =+YEAR -> 2025 | E2: =+YEAR -> 2025 | F2: =+YEAR -> 2025 | G2: =+YEAR -> 2025 | H2: =+YEAR -> 2025 | I2: =+YEAR -> 2025 | J2: =+YEAR -> 2025 | K2: =+YEAR -> 2025 | ... P2: =+YEAR -> 2025 | R2: =+YEAR_1 -> 2026 | S2: =+YEAR_1 -> 2026 | T2: =+YEAR_1 -> 2026 | U2: =+YEAR_1 -> 2026 | V2: =+YEAR_1 -> 2026 | W2: =+YEAR_1 -> 2026 | X2: =+YEAR_1 -> 2026 | Y2: =+YEAR_1 -> 2026 | ... AD2: =+YEAR_1 -> 2026 | AF2: =+YEAR_2 -> 2027 | AG2: =+YEAR_2 -> 2027 | AH2: =+YEAR_2 -> 2027 | AI2: =+YEAR_2 -> 2027 | AJ2: =+YEAR_2 -> 2027 | AK2: =+YEAR_2 -> 2027 | AL2: =+YEAR_2 -> 2027 | AM2: =+YEAR_2 -> 2027 | ... AR2: =+YEAR_2 -> 2027 | AT2: =+YEAR_3 -> 2028 | AU2: =+YEAR_3 -> 2028 | AV2: =+YEAR_3 -> 2028 | AW2: =+YEAR_3 -> 2028 | AX2: =+YEAR_3 -> 2028 | AY2: =+YEAR_3 -> 2028 | AZ2: =+YEAR_3 -> 2028 | BA2: =+YEAR_3 -> 2028 | ... BF2: =+YEAR_3 -> 2028 | BH2: =+YEAR_4 -> 2029 | BI2: =+YEAR_4 -> 2029 | BJ2: =+YEAR_4 -> 2029 | BK2: =+YEAR_4 -> 2029 | BL2: =+YEAR_4 -> 2029 | BM2: =+YEAR_4 -> 2029 | BN2: =+YEAR_4 -> 2029 | BO2: =+YEAR_4 -> 2029 | ... BT2: =+YEAR_4 -> 2029 | BV2: =+YEAR_5 -> 2030 | BW2: =+YEAR_5 -> 2030 | BX2: =+YEAR_5 -> 2030 | BY2: =+YEAR_5 -> 2030 | BZ2: =+YEAR_5 -> 2030 | CA2: =+YEAR_5 -> 2030 | CB2: =+YEAR_5 -> 2030 | CC2: =+YEAR_5 -> 2030 | ... CH2: =+YEAR_5 -> 2030
B3: Version | D3: P&L | E3: P&L | F3: P&L | G3: P&L | H3: P&L | I3: P&L | J3: P&L | K3: P&L | L3: P&L | M3: P&L | N3: P&L | O3: P&L | P3: P&L | R3: P&L | S3: P&L | T3: P&L | U3: P&L | V3: P&L | W3: P&L | X3: P&L | Y3: P&L | Z3: P&L | AA3: P&L | AB3: P&L | AC3: P&L | AD3: P&L | AF3: P&L | AG3: P&L | AH3: P&L | AI3: P&L | AJ3: P&L | AK3: P&L | AL3: P&L | AM3: P&L | AN3: P&L | AO3: P&L | AP3: P&L | AQ3: P&L | AR3: P&L | AT3: P&L | AU3: P&L | AV3: P&L | AW3: P&L | AX3: P&L | AY3: P&L | AZ3: P&L | BA3: P&L | BB3: P&L | BC3: P&L | BD3: P&L | BE3: P&L | BF3: P&L | BH3: P&L | BI3: P&L | BJ3: P&L | BK3: P&L | BL3: P&L | BM3: P&L | BN3: P&L | BO3: P&L | BP3: P&L | BQ3: P&L | BR3: P&L | BS3: P&L | BT3: P&L | BV3: P&L | BW3: P&L | BX3: P&L | BY3: P&L | BZ3: P&L | CA3: P&L | CB3: P&L | CC3: P&L | CD3: P&L | CE3: P&L | CF3: P&L | CG3: P&L | CH3: P&L
B4: Month | D4: 1 | E4: =+D4+1 -> 2 | F4: =+E4+1 -> 3 | G4: =+F4+1 -> 4 | H4: =+G4+1 -> 5 | I4: =+H4+1 -> 6 | J4: =+I4+1 -> 7 | K4: =+J4+1 -> 8 | L4: =+K4+1 -> 9 | ... O4: =+N4+1 -> 12 | P4: TOTAL | R4: 1 | S4: =+R4+1 -> 2 | T4: =+S4+1 -> 3 | U4: =+T4+1 -> 4 | V4: =+U4+1 -> 5 | W4: =+V4+1 -> 6 | X4: =+W4+1 -> 7 | Y4: =+X4+1 -> 8 | Z4: =+Y4+1 -> 9 | ... AC4: =+AB4+1 -> 12 | AD4: TOTAL | AF4: 1 | AG4: =+AF4+1 -> 2 | AH4: =+AG4+1 -> 3 | AI4: =+AH4+1 -> 4 | AJ4: =+AI4+1 -> 5 | AK4: =+AJ4+1 -> 6 | AL4: =+AK4+1 -> 7 | AM4: =+AL4+1 -> 8 | AN4: =+AM4+1 -> 9 | ... AQ4: =+AP4+1 -> 12 | AR4: TOTAL | AT4: 1 | AU4: =+AT4+1 -> 2 | AV4: =+AU4+1 -> 3 | AW4: =+AV4+1 -> 4 | AX4: =+AW4+1 -> 5 | AY4: =+AX4+1 -> 6 | AZ4: =+AY4+1 -> 7 | BA4: =+AZ4+1 -> 8 | BB4: =+BA4+1 -> 9 | ... BE4: =+BD4+1 -> 12 | BF4: TOTAL | BH4: 1 | BI4: =+BH4+1 -> 2 | BJ4: =+BI4+1 -> 3 | BK4: =+BJ4+1 -> 4 | BL4: =+BK4+1 -> 5 | BM4: =+BL4+1 -> 6 | BN4: =+BM4+1 -> 7 | BO4: =+BN4+1 -> 8 | BP4: =+BO4+1 -> 9 | ... BS4: =+BR4+1 -> 12 | BT4: TOTAL | BV4: 1 | BW4: =+BV4+1 -> 2 | BX4: =+BW4+1 -> 3 | BY4: =+BX4+1 -> 4 | BZ4: =+BY4+1 -> 5 | CA4: =+BZ4+1 -> 6 | CB4: =+CA4+1 -> 7 | CC4: =+CB4+1 -> 8 | CD4: =+CC4+1 -> 9 | ... CG4: =+CF4+1 -> 12 | CH4: TOTAL
B5: Quarter | D5: Q1 | E5: Q1 | F5: Q1 | G5: Q2 | H5: Q2 | I5: Q2 | J5: Q3 | K5: Q3 | L5: Q3 | M5: Q4 | N5: Q4 | O5: Q4 | R5: Q1 | S5: Q1 | T5: Q1 | U5: Q2 | V5: Q2 | W5: Q2 | X5: Q3 | Y5: Q3 | Z5: Q3 | AA5: Q4 | AB5: Q4 | AC5: Q4 | AF5: Q1 | AG5: Q1 | AH5: Q1 | AI5: Q2 | AJ5: Q2 | AK5: Q2 | AL5: Q3 | AM5: Q3 | AN5: Q3 | AO5: Q4 | AP5: Q4 | AQ5: Q4 | AT5: Q1 | AU5: Q1 | AV5: Q1 | AW5: Q2 | AX5: Q2 | AY5: Q2 | AZ5: Q3 | BA5: Q3 | BB5: Q3 | BC5: Q4 | BD5: Q4 | BE5: Q4 | BH5: Q1 | BI5: Q1 | BJ5: Q1 | BK5: Q2 | BL5: Q2 | BM5: Q2 | BN5: Q3 | BO5: Q3 | BP5: Q3 | BQ5: Q4 | BR5: Q4 | BS5: Q4 | BV5: Q1 | BW5: Q1 | BX5: Q1 | BY5: Q2 | BZ5: Q2 | CA5: Q2 | CB5: Q3 | CC5: Q3 | CD5: Q3 | CE5: Q4 | CF5: Q4 | CG5: Q4
B6: Active Months | D6: =+IF(D4<=MONTH,1,0) -> 1 | E6: =+IF(E4<=MONTH,1,0) -> 1 | F6: =+IF(F4<=MONTH,1,0) -> 1 | G6: =+IF(G4<=MONTH,1,0) -> 1 | H6: =+IF(H4<=MONTH,1,0) -> 1 | I6: =+IF(I4<=MONTH,1,0) -> 1 | J6: =+IF(J4<=MONTH,1,0) -> 1 | K6: =+IF(K4<=MONTH,1,0) -> 1 | ... O6: =+IF(O4<=MONTH,1,0) -> 1 | R6: =+IF(R4<=MONTH,1,0) -> 1 | S6: =+IF(S4<=MONTH,1,0) -> 1 | T6: =+IF(T4<=MONTH,1,0) -> 1 | U6: =+IF(U4<=MONTH,1,0) -> 1 | V6: =+IF(V4<=MONTH,1,0) -> 1 | W6: =+IF(W4<=MONTH,1,0) -> 1 | X6: =+IF(X4<=MONTH,1,0) -> 1 | Y6: =+IF(Y4<=MONTH,1,0) -> 1 | ... AC6: =+IF(AC4<=MONTH,1,0) -> 1 | AF6: =+IF(AF4<=MONTH,1,0) -> 1 | AG6: =+IF(AG4<=MONTH,1,0) -> 1 | AH6: =+IF(AH4<=MONTH,1,0) -> 1 | AI6: =+IF(AI4<=MONTH,1,0) -> 1 | AJ6: =+IF(AJ4<=MONTH,1,0) -> 1 | AK6: =+IF(AK4<=MONTH,1,0) -> 1 | AL6: =+IF(AL4<=MONTH,1,0) -> 1 | AM6: =+IF(AM4<=MONTH,1,0) -> 1 | ... AQ6: =+IF(AQ4<=MONTH,1,0) -> 1 | AT6: =+IF(AT4<=MONTH,1,0) -> 1 | AU6: =+IF(AU4<=MONTH,1,0) -> 1 | AV6: =+IF(AV4<=MONTH,1,0) -> 1 | AW6: =+IF(AW4<=MONTH,1,0) -> 1 | AX6: =+IF(AX4<=MONTH,1,0) -> 1 | AY6: =+IF(AY4<=MONTH,1,0) -> 1 | AZ6: =+IF(AZ4<=MONTH,1,0) -> 1 | BA6: =+IF(BA4<=MONTH,1,0) -> 1 | ... BE6: =+IF(BE4<=MONTH,1,0) -> 1 | BH6: =+IF(BH4<=MONTH,1,0) -> 1 | BI6: =+IF(BI4<=MONTH,1,0) -> 1 | BJ6: =+IF(BJ4<=MONTH,1,0) -> 1 | BK6: =+IF(BK4<=MONTH,1,0) -> 1 | BL6: =+IF(BL4<=MONTH,1,0) -> 1 | BM6: =+IF(BM4<=MONTH,1,0) -> 1 | BN6: =+IF(BN4<=MONTH,1,0) -> 1 | BO6: =+IF(BO4<=MONTH,1,0) -> 1 | ... BS6: =+IF(BS4<=MONTH,1,0) -> 1 | BV6: =+IF(BV4<=MONTH,1,0) -> 1 | BW6: =+IF(BW4<=MONTH,1,0) -> 1 | BX6: =+IF(BX4<=MONTH,1,0) -> 1 | BY6: =+IF(BY4<=MONTH,1,0) -> 1 | BZ6: =+IF(BZ4<=MONTH,1,0) -> 1 | CA6: =+IF(CA4<=MONTH,1,0) -> 1 | CB6: =+IF(CB4<=MONTH,1,0) -> 1 | CC6: =+IF(CC4<=MONTH,1,0) -> 1 | ... CG6: =+IF(CG4<=MONTH,1,0) -> 1
B10: in EUR | D10: =+D2 -> 2025 | E10: =+E2 -> 2025 | F10: =+F2 -> 2025 | G10: =+G2 -> 2025 | H10: =+H2 -> 2025 | I10: =+I2 -> 2025 | J10: =+J2 -> 2025 | K10: =+K2 -> 2025 | ... P10: =+P2 -> 2025 | R10: =+R2 -> 2026 | S10: =+S2 -> 2026 | T10: =+T2 -> 2026 | U10: =+U2 -> 2026 | V10: =+V2 -> 2026 | W10: =+W2 -> 2026 | X10: =+X2 -> 2026 | Y10: =+Y2 -> 2026 | ... AD10: =+AD2 -> 2026 | AF10: =+AF2 -> 2027 | AG10: =+AG2 -> 2027 | AH10: =+AH2 -> 2027 | AI10: =+AI2 -> 2027 | AJ10: =+AJ2 -> 2027 | AK10: =+AK2 -> 2027 | AL10: =+AL2 -> 2027 | AM10: =+AM2 -> 2027 | ... AR10: =+AR2 -> 2027 | AT10: =+AT2 -> 2028 | AU10: =+AU2 -> 2028 | AV10: =+AV2 -> 2028 | AW10: =+AW2 -> 2028 | AX10: =+AX2 -> 2028 | AY10: =+AY2 -> 2028 | AZ10: =+AZ2 -> 2028 | BA10: =+BA2 -> 2028 | ... BF10: =+BF2 -> 2028 | BH10: =+BH2 -> 2029 | BI10: =+BI2 -> 2029 | BJ10: =+BJ2 -> 2029 | BK10: =+BK2 -> 2029 | BL10: =+BL2 -> 2029 | BM10: =+BM2 -> 2029 | BN10: =+BN2 -> 2029 | BO10: =+BO2 -> 2029 | ... BT10: =+BT2 -> 2029 | BV10: =+BV2 -> 2030 | BW10: =+BW2 -> 2030 | BX10: =+BX2 -> 2030 | BY10: =+BY2 -> 2030 | BZ10: =+BZ2 -> 2030 | CA10: =+CA2 -> 2030 | CB10: =+CB2 -> 2030 | CC10: =+CC2 -> 2030 | ... CH10: =+CH2 -> 2030
C11: Key | D11: Jan | E11: Feb | F11: March | G11: April | H11: May | I11: June | J11: July | K11: Aug | L11: Sept | M11: Oct | N11: Nov | O11: Dec | P11: =+P4 -> TOTAL | R11: Jan | S11: Feb | T11: March | U11: April | V11: May | W11: June | X11: July | Y11: Aug | Z11: Sept | AA11: Oct | AB11: Nov | AC11: Dec | AD11: =+AD4 -> TOTAL | AF11: Jan | AG11: Feb | AH11: March | AI11: April | AJ11: May | AK11: June | AL11: July | AM11: Aug | AN11: Sept | AO11: Oct | AP11: Nov | AQ11: Dec | AR11: =+AR4 -> TOTAL | AT11: Jan | AU11: Feb | AV11: March | AW11: April | AX11: May | AY11: June | AZ11: July | BA11: Aug | BB11: Sept | BC11: Oct | BD11: Nov | BE11: Dec | BF11: =+BF4 -> TOTAL | BH11: Jan | BI11: Feb | BJ11: March | BK11: April | BL11: May | BM11: June | BN11: July | BO11: Aug | BP11: Sept | BQ11: Oct | BR11: Nov | BS11: Dec | BT11: =+BT4 -> TOTAL | BV11: Jan | BW11: Feb | BX11: March | BY11: April | BZ11: May | CA11: June | CB11: July | CC11: Aug | CD11: Sept | CE11: Oct | CF11: Nov | CG11: Dec | CH11: =+CH4 -> TOTAL
B12: ='Revenue Overview'!B12 -> Product 1 | C12: INC1 | D12: ='Revenue Overview'!D12 -> 0 | E12: ='Revenue Overview'!E12 -> 0 | F12: ='Revenue Overview'!F12 -> 0 | G12: ='Revenue Overview'!G12 -> 0 | H12: ='Revenue Overview'!H12 -> 0 | I12: ='Revenue Overview'!I12 -> 0 | J12: ='Revenue Overview'!J12 -> 0 | K12: ='Revenue Overview'!K12 -> 0 | ... O12: ='Revenue Overview'!O12 -> 1386 | P12: =SUM(D12:O12) -> 3601.5 | R12: ='Revenue Overview'!R12 -> 1680 | S12: ='Revenue Overview'!S12 -> 2100 | T12: ='Revenue Overview'!T12 -> 3150 | U12: ='Revenue Overview'!U12 -> 4200 | V12: ='Revenue Overview'!V12 -> 5250 | W12: ='Revenue Overview'!W12 -> 6993 | X12: ='Revenue Overview'!X12 -> 8925 | Y12: ='Revenue Overview'!Y12 -> 10500 | ... AC12: ='Revenue Overview'!AC12 -> 10500 | AD12: =SUM(R12:AC12) -> 84798 | AF12: ='Revenue Overview'!AF12 -> 11035.5 | AG12: ='Revenue Overview'!AG12 -> 11035.5 | AH12: ='Revenue Overview'!AH12 -> 11035.5 | AI12: ='Revenue Overview'!AI12 -> 11035.5 | AJ12: ='Revenue Overview'!AJ12 -> 11035.5 | AK12: ='Revenue Overview'!AK12 -> 11035.5 | AL12: ='Revenue Overview'!AL12 -> 11035.5 | AM12: ='Revenue Overview'!AM12 -> 11035.5 | ... AQ12: ='Revenue Overview'!AQ12 -> 11035.5 | AR12: =SUM(AF12:AQ12) -> 132426 | AT12: ='Revenue Overview'!AT12 -> 11432.778 | AU12: ='Revenue Overview'!AU12 -> 11432.778 | AV12: ='Revenue Overview'!AV12 -> 11432.778 | AW12: ='Revenue Overview'!AW12 -> 11432.778 | AX12: ='Revenue Overview'!AX12 -> 11432.778 | AY12: ='Revenue Overview'!AY12 -> 11432.778 | AZ12: ='Revenue Overview'!AZ12 -> 11432.778 | BA12: ='Revenue Overview'!BA12 -> 11432.778 | ... BE12: ='Revenue Overview'!BE12 -> 11432.778 | BF12: =SUM(AT12:BE12) -> 137193.34 | BH12: ='Revenue Overview'!BH12 -> 11832.925 | BI12: ='Revenue Overview'!BI12 -> 11832.925 | BJ12: ='Revenue Overview'!BJ12 -> 11832.925 | BK12: ='Revenue Overview'!BK12 -> 11832.925 | BL12: ='Revenue Overview'!BL12 -> 11832.925 | BM12: ='Revenue Overview'!BM12 -> 11832.925 | BN12: ='Revenue Overview'!BN12 -> 11832.925 | BO12: ='Revenue Overview'!BO12 -> 11832.925 | ... BS12: ='Revenue Overview'!BS12 -> 11832.925 | BT12: =SUM(BH12:BS12) -> 141995.1 | BV12: ='Revenue Overview'!BV12 -> 12247.078 | BW12: ='Revenue Overview'!BW12 -> 12247.078 | BX12: ='Revenue Overview'!BX12 -> 12247.078 | BY12: ='Revenue Overview'!BY12 -> 12247.078 | BZ12: ='Revenue Overview'!BZ12 -> 12247.078 | CA12: ='Revenue Overview'!CA12 -> 12247.078 | CB12: ='Revenue Overview'!CB12 -> 12247.078 | CC12: ='Revenue Overview'!CC12 -> 12247.078 | ... CG12: ='Revenue Overview'!CG12 -> 12247.078 | CH12: =SUM(BV12:CG12) -> 146964.93
B13: ='Revenue Overview'!B13 -> Product 2 | C13: INC2 | D13: ='Revenue Overview'!D13 -> 0 | E13: ='Revenue Overview'!E13 -> 0 | F13: ='Revenue Overview'!F13 -> 0 | G13: ='Revenue Overview'!G13 -> 0 | H13: ='Revenue Overview'!H13 -> 0 | I13: ='Revenue Overview'!I13 -> 0 | J13: ='Revenue Overview'!J13 -> 0 | K13: ='Revenue Overview'!K13 -> 0 | ... O13: ='Revenue Overview'!O13 -> 1386 | P13: =SUM(D13:O13) -> 3601.5 | R13: ='Revenue Overview'!R13 -> 1680 | S13: ='Revenue Overview'!S13 -> 2100 | T13: ='Revenue Overview'!T13 -> 3150 | U13: ='Revenue Overview'!U13 -> 4200 | V13: ='Revenue Overview'!V13 -> 5250 | W13: ='Revenue Overview'!W13 -> 6993 | X13: ='Revenue Overview'!X13 -> 8925 | Y13: ='Revenue Overview'!Y13 -> 10500 | ... AC13: ='Revenue Overview'!AC13 -> 10500 | AD13: =SUM(R13:AC13) -> 84798 | AF13: ='Revenue Overview'!AF13 -> 11035.5 | AG13: ='Revenue Overview'!AG13 -> 11035.5 | AH13: ='Revenue Overview'!AH13 -> 11035.5 | AI13: ='Revenue Overview'!AI13 -> 11035.5 | AJ13: ='Revenue Overview'!AJ13 -> 11035.5 | AK13: ='Revenue Overview'!AK13 -> 11035.5 | AL13: ='Revenue Overview'!AL13 -> 11035.5 | AM13: ='Revenue Overview'!AM13 -> 11035.5 | ... AQ13: ='Revenue Overview'!AQ13 -> 11035.5 | AR13: =SUM(AF13:AQ13) -> 132426 | AT13: ='Revenue Overview'!AT13 -> 11432.778 | AU13: ='Revenue Overview'!AU13 -> 11432.778 | AV13: ='Revenue Overview'!AV13 -> 11432.778 | AW13: ='Revenue Overview'!AW13 -> 11432.778 | AX13: ='Revenue Overview'!AX13 -> 11432.778 | AY13: ='Revenue Overview'!AY13 -> 11432.778 | AZ13: ='Revenue Overview'!AZ13 -> 11432.778 | BA13: ='Revenue Overview'!BA13 -> 11432.778 | ... BE13: ='Revenue Overview'!BE13 -> 11432.778 | BF13: =SUM(AT13:BE13) -> 137193.34 | BH13: ='Revenue Overview'!BH13 -> 11832.925 | BI13: ='Revenue Overview'!BI13 -> 11832.925 | BJ13: ='Revenue Overview'!BJ13 -> 11832.925 | BK13: ='Revenue Overview'!BK13 -> 11832.925 | BL13: ='Revenue Overview'!BL13 -> 11832.925 | BM13: ='Revenue Overview'!BM13 -> 11832.925 | BN13: ='Revenue Overview'!BN13 -> 11832.925 | BO13: ='Revenue Overview'!BO13 -> 11832.925 | ... BS13: ='Revenue Overview'!BS13 -> 11832.925 | BT13: =SUM(BH13:BS13) -> 141995.1 | BV13: ='Revenue Overview'!BV13 -> 12247.078 | BW13: ='Revenue Overview'!BW13 -> 12247.078 | BX13: ='Revenue Overview'!BX13 -> 12247.078 | BY13: ='Revenue Overview'!BY13 -> 12247.078 | BZ13: ='Revenue Overview'!BZ13 -> 12247.078 | CA13: ='Revenue Overview'!CA13 -> 12247.078 | CB13: ='Revenue Overview'!CB13 -> 12247.078 | CC13: ='Revenue Overview'!CC13 -> 12247.078 | ... CG13: ='Revenue Overview'!CG13 -> 12247.078 | CH13: =SUM(BV13:CG13) -> 146964.93
B14: ='Revenue Overview'!B14 -> Product 3 | C14: INC3 | D14: ='Revenue Overview'!D14 -> 0 | E14: ='Revenue Overview'!E14 -> 0 | F14: ='Revenue Overview'!F14 -> 0 | G14: ='Revenue Overview'!G14 -> 0 | H14: ='Revenue Overview'!H14 -> 0 | I14: ='Revenue Overview'!I14 -> 0 | J14: ='Revenue Overview'!J14 -> 0 | K14: ='Revenue Overview'!K14 -> 0 | ... O14: ='Revenue Overview'!O14 -> 1386 | P14: =SUM(D14:O14) -> 3601.5 | R14: ='Revenue Overview'!R14 -> 1680 | S14: ='Revenue Overview'!S14 -> 2100 | T14: ='Revenue Overview'!T14 -> 3150 | U14: ='Revenue Overview'!U14 -> 4200 | V14: ='Revenue Overview'!V14 -> 5250 | W14: ='Revenue Overview'!W14 -> 6993 | X14: ='Revenue Overview'!X14 -> 8925 | Y14: ='Revenue Overview'!Y14 -> 10500 | ... AC14: ='Revenue Overview'!AC14 -> 10500 | AD14: =SUM(R14:AC14) -> 84798 | AF14: ='Revenue Overview'!AF14 -> 11035.5 | AG14: ='Revenue Overview'!AG14 -> 11035.5 | AH14: ='Revenue Overview'!AH14 -> 11035.5 | AI14: ='Revenue Overview'!AI14 -> 11035.5 | AJ14: ='Revenue Overview'!AJ14 -> 11035.5 | AK14: ='Revenue Overview'!AK14 -> 11035.5 | AL14: ='Revenue Overview'!AL14 -> 11035.5 | AM14: ='Revenue Overview'!AM14 -> 11035.5 | ... AQ14: ='Revenue Overview'!AQ14 -> 11035.5 | AR14: =SUM(AF14:AQ14) -> 132426 | AT14: ='Revenue Overview'!AT14 -> 11432.778 | AU14: ='Revenue Overview'!AU14 -> 11432.778 | AV14: ='Revenue Overview'!AV14 -> 11432.778 | AW14: ='Revenue Overview'!AW14 -> 11432.778 | AX14: ='Revenue Overview'!AX14 -> 11432.778 | AY14: ='Revenue Overview'!AY14 -> 11432.778 | AZ14: ='Revenue Overview'!AZ14 -> 11432.778 | BA14: ='Revenue Overview'!BA14 -> 11432.778 | ... BE14: ='Revenue Overview'!BE14 -> 11432.778 | BF14: =SUM(AT14:BE14) -> 137193.34 | BH14: ='Revenue Overview'!BH14 -> 11832.925 | BI14: ='Revenue Overview'!BI14 -> 11832.925 | BJ14: ='Revenue Overview'!BJ14 -> 11832.925 | BK14: ='Revenue Overview'!BK14 -> 11832.925 | BL14: ='Revenue Overview'!BL14 -> 11832.925 | BM14: ='Revenue Overview'!BM14 -> 11832.925 | BN14: ='Revenue Overview'!BN14 -> 11832.925 | BO14: ='Revenue Overview'!BO14 -> 11832.925 | ... BS14: ='Revenue Overview'!BS14 -> 11832.925 | BT14: =SUM(BH14:BS14) -> 141995.1 | BV14: ='Revenue Overview'!BV14 -> 12247.078 | BW14: ='Revenue Overview'!BW14 -> 12247.078 | BX14: ='Revenue Overview'!BX14 -> 12247.078 | BY14: ='Revenue Overview'!BY14 -> 12247.078 | BZ14: ='Revenue Overview'!BZ14 -> 12247.078 | CA14: ='Revenue Overview'!CA14 -> 12247.078 | CB14: ='Revenue Overview'!CB14 -> 12247.078 | CC14: ='Revenue Overview'!CC14 -> 12247.078 | ... CG14: ='Revenue Overview'!CG14 -> 12247.078 | CH14: =SUM(BV14:CG14) -> 146964.93
B15: ='Revenue Overview'!B15 -> Product 4 | C15: INC4 | D15: ='Revenue Overview'!D15 -> 0 | E15: ='Revenue Overview'!E15 -> 0 | F15: ='Revenue Overview'!F15 -> 0 | G15: ='Revenue Overview'!G15 -> 0 | H15: ='Revenue Overview'!H15 -> 0 | I15: ='Revenue Overview'!I15 -> 0 | J15: ='Revenue Overview'!J15 -> 0 | K15: ='Revenue Overview'!K15 -> 0 | ... O15: ='Revenue Overview'!O15 -> 693 | P15: =SUM(D15:O15) -> 1218 | R15: ='Revenue Overview'!R15 -> 840 | S15: ='Revenue Overview'!S15 -> 1050 | T15: ='Revenue Overview'!T15 -> 1575 | U15: ='Revenue Overview'!U15 -> 1575 | V15: ='Revenue Overview'!V15 -> 2100 | W15: ='Revenue Overview'!W15 -> 2625 | X15: ='Revenue Overview'!X15 -> 3675 | Y15: ='Revenue Overview'!Y15 -> 5250 | ... AC15: ='Revenue Overview'!AC15 -> 5250 | AD15: =SUM(R15:AC15) -> 39690 | AF15: ='Revenue Overview'!AF15 -> 5517.75 | AG15: ='Revenue Overview'!AG15 -> 5517.75 | AH15: ='Revenue Overview'!AH15 -> 5517.75 | AI15: ='Revenue Overview'!AI15 -> 5517.75 | AJ15: ='Revenue Overview'!AJ15 -> 5517.75 | AK15: ='Revenue Overview'!AK15 -> 5517.75 | AL15: ='Revenue Overview'!AL15 -> 5517.75 | AM15: ='Revenue Overview'!AM15 -> 5517.75 | ... AQ15: ='Revenue Overview'!AQ15 -> 5517.75 | AR15: =SUM(AF15:AQ15) -> 66213 | AT15: ='Revenue Overview'!AT15 -> 5716.389 | AU15: ='Revenue Overview'!AU15 -> 5716.389 | AV15: ='Revenue Overview'!AV15 -> 5716.389 | AW15: ='Revenue Overview'!AW15 -> 5716.389 | AX15: ='Revenue Overview'!AX15 -> 5716.389 | AY15: ='Revenue Overview'!AY15 -> 5716.389 | AZ15: ='Revenue Overview'!AZ15 -> 5716.389 | BA15: ='Revenue Overview'!BA15 -> 5716.389 | ... BE15: ='Revenue Overview'!BE15 -> 5716.389 | BF15: =SUM(AT15:BE15) -> 68596.668 | BH15: ='Revenue Overview'!BH15 -> 5916.4626 | BI15: ='Revenue Overview'!BI15 -> 5916.4626 | BJ15: ='Revenue Overview'!BJ15 -> 5916.4626 | BK15: ='Revenue Overview'!BK15 -> 5916.4626 | BL15: ='Revenue Overview'!BL15 -> 5916.4626 | BM15: ='Revenue Overview'!BM15 -> 5916.4626 | BN15: ='Revenue Overview'!BN15 -> 5916.4626 | BO15: ='Revenue Overview'!BO15 -> 5916.4626 | ... BS15: ='Revenue Overview'!BS15 -> 5916.4626 | BT15: =SUM(BH15:BS15) -> 70997.551 | BV15: ='Revenue Overview'!BV15 -> 6123.5388 | BW15: ='Revenue Overview'!BW15 -> 6123.5388 | BX15: ='Revenue Overview'!BX15 -> 6123.5388 | BY15: ='Revenue Overview'!BY15 -> 6123.5388 | BZ15: ='Revenue Overview'!BZ15 -> 6123.5388 | CA15: ='Revenue Overview'!CA15 -> 6123.5388 | CB15: ='Revenue Overview'!CB15 -> 6123.5388 | CC15: ='Revenue Overview'!CC15 -> 6123.5388 | ... CG15: ='Revenue Overview'!CG15 -> 6123.5388 | CH15: =SUM(BV15:CG15) -> 73482.466
B16: ='Revenue Overview'!B16 -> Product 5 | C16: INC5 | D16: ='Revenue Overview'!D16 -> 0 | E16: ='Revenue Overview'!E16 -> 0 | F16: ='Revenue Overview'!F16 -> 0 | G16: ='Revenue Overview'!G16 -> 0 | H16: ='Revenue Overview'!H16 -> 0 | I16: ='Revenue Overview'!I16 -> 0 | J16: ='Revenue Overview'!J16 -> 0 | K16: ='Revenue Overview'!K16 -> 0 | ... O16: ='Revenue Overview'!O16 -> 693 | P16: =SUM(D16:O16) -> 1218 | R16: ='Revenue Overview'!R16 -> 840 | S16: ='Revenue Overview'!S16 -> 1050 | T16: ='Revenue Overview'!T16 -> 1575 | U16: ='Revenue Overview'!U16 -> 1575 | V16: ='Revenue Overview'!V16 -> 2100 | W16: ='Revenue Overview'!W16 -> 2625 | X16: ='Revenue Overview'!X16 -> 3675 | Y16: ='Revenue Overview'!Y16 -> 5250 | ... AC16: ='Revenue Overview'!AC16 -> 5250 | AD16: =SUM(R16:AC16) -> 39690 | AF16: ='Revenue Overview'!AF16 -> 5517.75 | AG16: ='Revenue Overview'!AG16 -> 5517.75 | AH16: ='Revenue Overview'!AH16 -> 5517.75 | AI16: ='Revenue Overview'!AI16 -> 5517.75 | AJ16: ='Revenue Overview'!AJ16 -> 5517.75 | AK16: ='Revenue Overview'!AK16 -> 5517.75 | AL16: ='Revenue Overview'!AL16 -> 5517.75 | AM16: ='Revenue Overview'!AM16 -> 5517.75 | ... AQ16: ='Revenue Overview'!AQ16 -> 5517.75 | AR16: =SUM(AF16:AQ16) -> 66213 | AT16: ='Revenue Overview'!AT16 -> 5716.389 | AU16: ='Revenue Overview'!AU16 -> 5716.389 | AV16: ='Revenue Overview'!AV16 -> 5716.389 | AW16: ='Revenue Overview'!AW16 -> 5716.389 | AX16: ='Revenue Overview'!AX16 -> 5716.389 | AY16: ='Revenue Overview'!AY16 -> 5716.389 | AZ16: ='Revenue Overview'!AZ16 -> 5716.389 | BA16: ='Revenue Overview'!BA16 -> 5716.389 | ... BE16: ='Revenue Overview'!BE16 -> 5716.389 | BF16: =SUM(AT16:BE16) -> 68596.668 | BH16: ='Revenue Overview'!BH16 -> 5916.4626 | BI16: ='Revenue Overview'!BI16 -> 5916.4626 | BJ16: ='Revenue Overview'!BJ16 -> 5916.4626 | BK16: ='Revenue Overview'!BK16 -> 5916.4626 | BL16: ='Revenue Overview'!BL16 -> 5916.4626 | BM16: ='Revenue Overview'!BM16 -> 5916.4626 | BN16: ='Revenue Overview'!BN16 -> 5916.4626 | BO16: ='Revenue Overview'!BO16 -> 5916.4626 | ... BS16: ='Revenue Overview'!BS16 -> 5916.4626 | BT16: =SUM(BH16:BS16) -> 70997.551 | BV16: ='Revenue Overview'!BV16 -> 6123.5388 | BW16: ='Revenue Overview'!BW16 -> 6123.5388 | BX16: ='Revenue Overview'!BX16 -> 6123.5388 | BY16: ='Revenue Overview'!BY16 -> 6123.5388 | BZ16: ='Revenue Overview'!BZ16 -> 6123.5388 | CA16: ='Revenue Overview'!CA16 -> 6123.5388 | CB16: ='Revenue Overview'!CB16 -> 6123.5388 | CC16: ='Revenue Overview'!CC16 -> 6123.5388 | ... CG16: ='Revenue Overview'!CG16 -> 6123.5388 | CH16: =SUM(BV16:CG16) -> 73482.466
B17: ='Revenue Overview'!B17 -> Product 6 | C17: INC6 | D17: ='Revenue Overview'!D17 -> 0 | E17: ='Revenue Overview'!E17 -> 0 | F17: ='Revenue Overview'!F17 -> 0 | G17: ='Revenue Overview'!G17 -> 0 | H17: ='Revenue Overview'!H17 -> 0 | I17: ='Revenue Overview'!I17 -> 0 | J17: ='Revenue Overview'!J17 -> 0 | K17: ='Revenue Overview'!K17 -> 0 | ... O17: ='Revenue Overview'!O17 -> 693 | P17: =SUM(D17:O17) -> 1218 | R17: ='Revenue Overview'!R17 -> 840 | S17: ='Revenue Overview'!S17 -> 1050 | T17: ='Revenue Overview'!T17 -> 1575 | U17: ='Revenue Overview'!U17 -> 1575 | V17: ='Revenue Overview'!V17 -> 2100 | W17: ='Revenue Overview'!W17 -> 2625 | X17: ='Revenue Overview'!X17 -> 3675 | Y17: ='Revenue Overview'!Y17 -> 5250 | ... AC17: ='Revenue Overview'!AC17 -> 5250 | AD17: =SUM(R17:AC17) -> 39690 | AF17: ='Revenue Overview'!AF17 -> 5517.75 | AG17: ='Revenue Overview'!AG17 -> 5517.75 | AH17: ='Revenue Overview'!AH17 -> 5517.75 | AI17: ='Revenue Overview'!AI17 -> 5517.75 | AJ17: ='Revenue Overview'!AJ17 -> 5517.75 | AK17: ='Revenue Overview'!AK17 -> 5517.75 | AL17: ='Revenue Overview'!AL17 -> 5517.75 | AM17: ='Revenue Overview'!AM17 -> 5517.75 | ... AQ17: ='Revenue Overview'!AQ17 -> 5517.75 | AR17: =SUM(AF17:AQ17) -> 66213 | AT17: ='Revenue Overview'!AT17 -> 5716.389 | AU17: ='Revenue Overview'!AU17 -> 5716.389 | AV17: ='Revenue Overview'!AV17 -> 5716.389 | AW17: ='Revenue Overview'!AW17 -> 5716.389 | AX17: ='Revenue Overview'!AX17 -> 5716.389 | AY17: ='Revenue Overview'!AY17 -> 5716.389 | AZ17: ='Revenue Overview'!AZ17 -> 5716.389 | BA17: ='Revenue Overview'!BA17 -> 5716.389 | ... BE17: ='Revenue Overview'!BE17 -> 5716.389 | BF17: =SUM(AT17:BE17) -> 68596.668 | BH17: ='Revenue Overview'!BH17 -> 5916.4626 | BI17: ='Revenue Overview'!BI17 -> 5916.4626 | BJ17: ='Revenue Overview'!BJ17 -> 5916.4626 | BK17: ='Revenue Overview'!BK17 -> 5916.4626 | BL17: ='Revenue Overview'!BL17 -> 5916.4626 | BM17: ='Revenue Overview'!BM17 -> 5916.4626 | BN17: ='Revenue Overview'!BN17 -> 5916.4626 | BO17: ='Revenue Overview'!BO17 -> 5916.4626 | ... BS17: ='Revenue Overview'!BS17 -> 5916.4626 | BT17: =SUM(BH17:BS17) -> 70997.551 | BV17: ='Revenue Overview'!BV17 -> 6123.5388 | BW17: ='Revenue Overview'!BW17 -> 6123.5388 | BX17: ='Revenue Overview'!BX17 -> 6123.5388 | BY17: ='Revenue Overview'!BY17 -> 6123.5388 | BZ17: ='Revenue Overview'!BZ17 -> 6123.5388 | CA17: ='Revenue Overview'!CA17 -> 6123.5388 | CB17: ='Revenue Overview'!CB17 -> 6123.5388 | CC17: ='Revenue Overview'!CC17 -> 6123.5388 | ... CG17: ='Revenue Overview'!CG17 -> 6123.5388 | CH17: =SUM(BV17:CG17) -> 73482.466
B18: ='Revenue Overview'!B18 -> Product 7 | C18: INC7 | V18: ='Revenue Overview'!V18 -> 1050 | W18: ='Revenue Overview'!W18 -> 2100 | X18: ='Revenue Overview'!X18 -> 3150 | Y18: ='Revenue Overview'!Y18 -> 4725 | Z18: ='Revenue Overview'!Z18 -> 4725 | AA18: ='Revenue Overview'!AA18 -> 4725 | AB18: ='Revenue Overview'!AB18 -> 4725 | AC18: ='Revenue Overview'!AC18 -> 4725 | AD18: =SUM(R18:AC18) -> 29925 | AF18: ='Revenue Overview'!AF18 -> 4965.975 | AG18: ='Revenue Overview'!AG18 -> 4965.975 | AH18: ='Revenue Overview'!AH18 -> 4965.975 | AI18: ='Revenue Overview'!AI18 -> 4965.975 | AJ18: ='Revenue Overview'!AJ18 -> 4965.975 | AK18: ='Revenue Overview'!AK18 -> 4965.975 | AL18: ='Revenue Overview'!AL18 -> 4965.975 | AM18: ='Revenue Overview'!AM18 -> 4965.975 | ... AQ18: ='Revenue Overview'!AQ18 -> 4965.975 | AR18: =SUM(AF18:AQ18) -> 59591.7 | AT18: ='Revenue Overview'!AT18 -> 5144.7501 | AU18: ='Revenue Overview'!AU18 -> 5144.7501 | AV18: ='Revenue Overview'!AV18 -> 5144.7501 | AW18: ='Revenue Overview'!AW18 -> 5144.7501 | AX18: ='Revenue Overview'!AX18 -> 5144.7501 | AY18: ='Revenue Overview'!AY18 -> 5144.7501 | AZ18: ='Revenue Overview'!AZ18 -> 5144.7501 | BA18: ='Revenue Overview'!BA18 -> 5144.7501 | ... BE18: ='Revenue Overview'!BE18 -> 5144.7501 | BF18: =SUM(AT18:BE18) -> 61737.001 | BH18: ='Revenue Overview'!BH18 -> 5324.8164 | BI18: ='Revenue Overview'!BI18 -> 5324.8164 | BJ18: ='Revenue Overview'!BJ18 -> 5324.8164 | BK18: ='Revenue Overview'!BK18 -> 5324.8164 | BL18: ='Revenue Overview'!BL18 -> 5324.8164 | BM18: ='Revenue Overview'!BM18 -> 5324.8164 | BN18: ='Revenue Overview'!BN18 -> 5324.8164 | BO18: ='Revenue Overview'!BO18 -> 5324.8164 | ... BS18: ='Revenue Overview'!BS18 -> 5324.8164 | BT18: =SUM(BH18:BS18) -> 63897.796 | BV18: ='Revenue Overview'!BV18 -> 5511.1849 | BW18: ='Revenue Overview'!BW18 -> 5511.1849 | BX18: ='Revenue Overview'!BX18 -> 5511.1849 | BY18: ='Revenue Overview'!BY18 -> 5511.1849 | BZ18: ='Revenue Overview'!BZ18 -> 5511.1849 | CA18: ='Revenue Overview'!CA18 -> 5511.1849 | CB18: ='Revenue Overview'!CB18 -> 5511.1849 | CC18: ='Revenue Overview'!CC18 -> 5511.1849 | ... CG18: ='Revenue Overview'!CG18 -> 5511.1849 | CH18: =SUM(BV18:CG18) -> 66134.219
B19: ='Revenue Overview'!B19 -> Product 8 | C19: INC8 | V19: ='Revenue Overview'!V19 -> 1050 | W19: ='Revenue Overview'!W19 -> 2100 | X19: ='Revenue Overview'!X19 -> 3150 | Y19: ='Revenue Overview'!Y19 -> 4725 | Z19: ='Revenue Overview'!Z19 -> 4725 | AA19: ='Revenue Overview'!AA19 -> 4725 | AB19: ='Revenue Overview'!AB19 -> 4725 | AC19: ='Revenue Overview'!AC19 -> 4725 | AD19: =SUM(R19:AC19) -> 29925 | AF19: ='Revenue Overview'!AF19 -> 4965.975 | AG19: ='Revenue Overview'!AG19 -> 4965.975 | AH19: ='Revenue Overview'!AH19 -> 4965.975 | AI19: ='Revenue Overview'!AI19 -> 4965.975 | AJ19: ='Revenue Overview'!AJ19 -> 4965.975 | AK19: ='Revenue Overview'!AK19 -> 4965.975 | AL19: ='Revenue Overview'!AL19 -> 4965.975 | AM19: ='Revenue Overview'!AM19 -> 4965.975 | ... AQ19: ='Revenue Overview'!AQ19 -> 4965.975 | AR19: =SUM(AF19:AQ19) -> 59591.7 | AT19: ='Revenue Overview'!AT19 -> 5144.7501 | AU19: ='Revenue Overview'!AU19 -> 5144.7501 | AV19: ='Revenue Overview'!AV19 -> 5144.7501 | AW19: ='Revenue Overview'!AW19 -> 5144.7501 | AX19: ='Revenue Overview'!AX19 -> 5144.7501 | AY19: ='Revenue Overview'!AY19 -> 5144.7501 | AZ19: ='Revenue Overview'!AZ19 -> 5144.7501 | BA19: ='Revenue Overview'!BA19 -> 5144.7501 | ... BE19: ='Revenue Overview'!BE19 -> 5144.7501 | BF19: =SUM(AT19:BE19) -> 61737.001 | BH19: ='Revenue Overview'!BH19 -> 5324.8164 | BI19: ='Revenue Overview'!BI19 -> 5324.8164 | BJ19: ='Revenue Overview'!BJ19 -> 5324.8164 | BK19: ='Revenue Overview'!BK19 -> 5324.8164 | BL19: ='Revenue Overview'!BL19 -> 5324.8164 | BM19: ='Revenue Overview'!BM19 -> 5324.8164 | BN19: ='Revenue Overview'!BN19 -> 5324.8164 | BO19: ='Revenue Overview'!BO19 -> 5324.8164 | ... BS19: ='Revenue Overview'!BS19 -> 5324.8164 | BT19: =SUM(BH19:BS19) -> 63897.796 | BV19: ='Revenue Overview'!BV19 -> 5511.1849 | BW19: ='Revenue Overview'!BW19 -> 5511.1849 | BX19: ='Revenue Overview'!BX19 -> 5511.1849 | BY19: ='Revenue Overview'!BY19 -> 5511.1849 | BZ19: ='Revenue Overview'!BZ19 -> 5511.1849 | CA19: ='Revenue Overview'!CA19 -> 5511.1849 | CB19: ='Revenue Overview'!CB19 -> 5511.1849 | CC19: ='Revenue Overview'!CC19 -> 5511.1849 | ... CG19: ='Revenue Overview'!CG19 -> 5511.1849 | CH19: =SUM(BV19:CG19) -> 66134.219
B20: ='Revenue Overview'!B20 -> Product 9 | C20: INC9 | V20: ='Revenue Overview'!V20 -> 1050 | W20: ='Revenue Overview'!W20 -> 2100 | X20: ='Revenue Overview'!X20 -> 3150 | Y20: ='Revenue Overview'!Y20 -> 4725 | Z20: ='Revenue Overview'!Z20 -> 4725 | AA20: ='Revenue Overview'!AA20 -> 4725 | AB20: ='Revenue Overview'!AB20 -> 4725 | AC20: ='Revenue Overview'!AC20 -> 4725 | AD20: =SUM(R20:AC20) -> 29925 | AF20: ='Revenue Overview'!AF20 -> 4965.975 | AG20: ='Revenue Overview'!AG20 -> 4965.975 | AH20: ='Revenue Overview'!AH20 -> 4965.975 | AI20: ='Revenue Overview'!AI20 -> 4965.975 | AJ20: ='Revenue Overview'!AJ20 -> 4965.975 | AK20: ='Revenue Overview'!AK20 -> 4965.975 | AL20: ='Revenue Overview'!AL20 -> 4965.975 | AM20: ='Revenue Overview'!AM20 -> 4965.975 | ... AQ20: ='Revenue Overview'!AQ20 -> 4965.975 | AR20: =SUM(AF20:AQ20) -> 59591.7 | AT20: ='Revenue Overview'!AT20 -> 5144.7501 | AU20: ='Revenue Overview'!AU20 -> 5144.7501 | AV20: ='Revenue Overview'!AV20 -> 5144.7501 | AW20: ='Revenue Overview'!AW20 -> 5144.7501 | AX20: ='Revenue Overview'!AX20 -> 5144.7501 | AY20: ='Revenue Overview'!AY20 -> 5144.7501 | AZ20: ='Revenue Overview'!AZ20 -> 5144.7501 | BA20: ='Revenue Overview'!BA20 -> 5144.7501 | ... BE20: ='Revenue Overview'!BE20 -> 5144.7501 | BF20: =SUM(AT20:BE20) -> 61737.001 | BH20: ='Revenue Overview'!BH20 -> 5324.8164 | BI20: ='Revenue Overview'!BI20 -> 5324.8164 | BJ20: ='Revenue Overview'!BJ20 -> 5324.8164 | BK20: ='Revenue Overview'!BK20 -> 5324.8164 | BL20: ='Revenue Overview'!BL20 -> 5324.8164 | BM20: ='Revenue Overview'!BM20 -> 5324.8164 | BN20: ='Revenue Overview'!BN20 -> 5324.8164 | BO20: ='Revenue Overview'!BO20 -> 5324.8164 | ... BS20: ='Revenue Overview'!BS20 -> 5324.8164 | BT20: =SUM(BH20:BS20) -> 63897.796 | BV20: ='Revenue Overview'!BV20 -> 5511.1849 | BW20: ='Revenue Overview'!BW20 -> 5511.1849 | BX20: ='Revenue Overview'!BX20 -> 5511.1849 | BY20: ='Revenue Overview'!BY20 -> 5511.1849 | BZ20: ='Revenue Overview'!BZ20 -> 5511.1849 | CA20: ='Revenue Overview'!CA20 -> 5511.1849 | CB20: ='Revenue Overview'!CB20 -> 5511.1849 | CC20: ='Revenue Overview'!CC20 -> 5511.1849 | ... CG20: ='Revenue Overview'!CG20 -> 5511.1849 | CH20: =SUM(BV20:CG20) -> 66134.219
B21: ='Revenue Overview'!B21 -> Product 10 | C21: INC10 | V21: ='Revenue Overview'!V21 -> 1050 | W21: ='Revenue Overview'!W21 -> 2100 | X21: ='Revenue Overview'!X21 -> 3150 | Y21: ='Revenue Overview'!Y21 -> 4725 | Z21: ='Revenue Overview'!Z21 -> 4725 | AA21: ='Revenue Overview'!AA21 -> 4725 | AB21: ='Revenue Overview'!AB21 -> 4725 | AC21: ='Revenue Overview'!AC21 -> 4725 | AD21: =SUM(R21:AC21) -> 29925 | AF21: ='Revenue Overview'!AF21 -> 4965.975 | AG21: ='Revenue Overview'!AG21 -> 4965.975 | AH21: ='Revenue Overview'!AH21 -> 4965.975 | AI21: ='Revenue Overview'!AI21 -> 4965.975 | AJ21: ='Revenue Overview'!AJ21 -> 4965.975 | AK21: ='Revenue Overview'!AK21 -> 4965.975 | AL21: ='Revenue Overview'!AL21 -> 4965.975 | AM21: ='Revenue Overview'!AM21 -> 4965.975 | ... AQ21: ='Revenue Overview'!AQ21 -> 4965.975 | AR21: =SUM(AF21:AQ21) -> 59591.7 | AT21: ='Revenue Overview'!AT21 -> 5144.7501 | AU21: ='Revenue Overview'!AU21 -> 5144.7501 | AV21: ='Revenue Overview'!AV21 -> 5144.7501 | AW21: ='Revenue Overview'!AW21 -> 5144.7501 | AX21: ='Revenue Overview'!AX21 -> 5144.7501 | AY21: ='Revenue Overview'!AY21 -> 5144.7501 | AZ21: ='Revenue Overview'!AZ21 -> 5144.7501 | BA21: ='Revenue Overview'!BA21 -> 5144.7501 | ... BE21: ='Revenue Overview'!BE21 -> 5144.7501 | BF21: =SUM(AT21:BE21) -> 61737.001 | BH21: ='Revenue Overview'!BH21 -> 5324.8164 | BI21: ='Revenue Overview'!BI21 -> 5324.8164 | BJ21: ='Revenue Overview'!BJ21 -> 5324.8164 | BK21: ='Revenue Overview'!BK21 -> 5324.8164 | BL21: ='Revenue Overview'!BL21 -> 5324.8164 | BM21: ='Revenue Overview'!BM21 -> 5324.8164 | BN21: ='Revenue Overview'!BN21 -> 5324.8164 | BO21: ='Revenue Overview'!BO21 -> 5324.8164 | ... BS21: ='Revenue Overview'!BS21 -> 5324.8164 | BT21: =SUM(BH21:BS21) -> 63897.796 | BV21: ='Revenue Overview'!BV21 -> 5511.1849 | BW21: ='Revenue Overview'!BW21 -> 5511.1849 | BX21: ='Revenue Overview'!BX21 -> 5511.1849 | BY21: ='Revenue Overview'!BY21 -> 5511.1849 | BZ21: ='Revenue Overview'!BZ21 -> 5511.1849 | CA21: ='Revenue Overview'!CA21 -> 5511.1849 | CB21: ='Revenue Overview'!CB21 -> 5511.1849 | CC21: ='Revenue Overview'!CC21 -> 5511.1849 | ... CG21: ='Revenue Overview'!CG21 -> 5511.1849 | CH21: =SUM(BV21:CG21) -> 66134.219
B22: TOTAL Revenues | D22: =SUM(D12:D17) -> 0 | E22: =SUM(E12:E17) -> 0 | F22: =SUM(F12:F17) -> 0 | G22: =SUM(G12:G17) -> 0 | H22: =SUM(H12:H17) -> 0 | I22: =SUM(I12:I17) -> 0 | J22: =SUM(J12:J17) -> 0 | K22: =SUM(K12:K17) -> 0 | ... O22: =SUM(O12:O17) -> 6237 | P22: =SUM(D22:O22) -> 14458.5 | R22: =SUM(R12:R17) -> 7560 | S22: =SUM(S12:S17) -> 9450 | T22: =SUM(T12:T17) -> 14175 | U22: =SUM(U12:U17) -> 17325 | V22: =SUM(V12:V17) -> 22050 | W22: =SUM(W12:W17) -> 28854 | X22: =SUM(X12:X17) -> 37800 | Y22: =SUM(Y12:Y17) -> 47250 | ... AC22: =SUM(AC12:AC17) -> 47250 | AD22: =SUM(R22:AC22) -> 373464 | AF22: =SUM(AF12:AF17) -> 49659.75 | AG22: =SUM(AG12:AG17) -> 49659.75 | AH22: =SUM(AH12:AH17) -> 49659.75 | AI22: =SUM(AI12:AI17) -> 49659.75 | AJ22: =SUM(AJ12:AJ17) -> 49659.75 | AK22: =SUM(AK12:AK17) -> 49659.75 | AL22: =SUM(AL12:AL17) -> 49659.75 | AM22: =SUM(AM12:AM17) -> 49659.75 | ... AQ22: =SUM(AQ12:AQ17) -> 49659.75 | AR22: =SUM(AF22:AQ22) -> 595917 | AT22: =SUM(AT12:AT17) -> 51447.501 | AU22: =SUM(AU12:AU17) -> 51447.501 | AV22: =SUM(AV12:AV17) -> 51447.501 | AW22: =SUM(AW12:AW17) -> 51447.501 | AX22: =SUM(AX12:AX17) -> 51447.501 | AY22: =SUM(AY12:AY17) -> 51447.501 | AZ22: =SUM(AZ12:AZ17) -> 51447.501 | BA22: =SUM(BA12:BA17) -> 51447.501 | ... BE22: =SUM(BE12:BE17) -> 51447.501 | BF22: =SUM(AT22:BE22) -> 617370.01 | BH22: =SUM(BH12:BH17) -> 53248.164 | BI22: =SUM(BI12:BI17) -> 53248.164 | BJ22: =SUM(BJ12:BJ17) -> 53248.164 | BK22: =SUM(BK12:BK17) -> 53248.164 | BL22: =SUM(BL12:BL17) -> 53248.164 | BM22: =SUM(BM12:BM17) -> 53248.164 | BN22: =SUM(BN12:BN17) -> 53248.164 | BO22: =SUM(BO12:BO17) -> 53248.164 | ... BS22: =SUM(BS12:BS17) -> 53248.164 | BT22: =SUM(BH22:BS22) -> 638977.96 | BV22: =SUM(BV12:BV17) -> 55111.849 | BW22: =SUM(BW12:BW17) -> 55111.849 | BX22: =SUM(BX12:BX17) -> 55111.849 | BY22: =SUM(BY12:BY17) -> 55111.849 | BZ22: =SUM(BZ12:BZ17) -> 55111.849 | CA22: =SUM(CA12:CA17) -> 55111.849 | CB22: =SUM(CB12:CB17) -> 55111.849 | CC22: =SUM(CC12:CC17) -> 55111.849 | ... CG22: =SUM(CG12:CG17) -> 55111.849 | CH22: =SUM(BV22:CG22) -> 661342.19
B24: TOTAL REVENUES | D24: =SUM(D22) -> 0 | E24: =SUM(E22) -> 0 | F24: =SUM(F22) -> 0 | G24: =SUM(G22) -> 0 | H24: =SUM(H22) -> 0 | I24: =SUM(I22) -> 0 | J24: =SUM(J22) -> 0 | K24: =SUM(K22) -> 0 | ... P24: =SUM(P22) -> 14458.5 | R24: =SUM(R22) -> 7560 | S24: =SUM(S22) -> 9450 | T24: =SUM(T22) -> 14175 | U24: =SUM(U22) -> 17325 | V24: =SUM(V22) -> 22050 | W24: =SUM(W22) -> 28854 | X24: =SUM(X22) -> 37800 | Y24: =SUM(Y22) -> 47250 | ... AD24: =SUM(AD22) -> 373464 | AF24: =SUM(AF22) -> 49659.75 | AG24: =SUM(AG22) -> 49659.75 | AH24: =SUM(AH22) -> 49659.75 | AI24: =SUM(AI22) -> 49659.75 | AJ24: =SUM(AJ22) -> 49659.75 | AK24: =SUM(AK22) -> 49659.75 | AL24: =SUM(AL22) -> 49659.75 | AM24: =SUM(AM22) -> 49659.75 | ... AR24: =SUM(AR22) -> 595917 | AT24: =SUM(AT22) -> 51447.501 | AU24: =SUM(AU22) -> 51447.501 | AV24: =SUM(AV22) -> 51447.501 | AW24: =SUM(AW22) -> 51447.501 | AX24: =SUM(AX22) -> 51447.501 | AY24: =SUM(AY22) -> 51447.501 | AZ24: =SUM(AZ22) -> 51447.501 | BA24: =SUM(BA22) -> 51447.501 | ... BF24: =SUM(BF22) -> 617370.01 | BH24: =SUM(BH22) -> 53248.164 | BI24: =SUM(BI22) -> 53248.164 | BJ24: =SUM(BJ22) -> 53248.164 | BK24: =SUM(BK22) -> 53248.164 | BL24: =SUM(BL22) -> 53248.164 | BM24: =SUM(BM22) -> 53248.164 | BN24: =SUM(BN22) -> 53248.164 | BO24: =SUM(BO22) -> 53248.164 | ... BT24: =SUM(BT22) -> 638977.96 | BV24: =SUM(BV22) -> 55111.849 | BW24: =SUM(BW22) -> 55111.849 | BX24: =SUM(BX22) -> 55111.849 | BY24: =SUM(BY22) -> 55111.849 | BZ24: =SUM(BZ22) -> 55111.849 | CA24: =SUM(CA22) -> 55111.849 | CB24: =SUM(CB22) -> 55111.849 | CC24: =SUM(CC22) -> 55111.849 | ... CH24: =SUM(CH22) -> 661342.19
A26: TO DO | B26: =Operational!B12 -> Main Office | C26: =Operational!C12 -> O1 | D26: =Operational!D12 -> 0 | E26: =Operational!E12 -> 0 | F26: =Operational!F12 -> 0 | G26: =Operational!G12 -> 0 | H26: =Operational!H12 -> 0 | I26: =Operational!I12 -> 0 | ... O26: =Operational!O12 -> -3000 | P26: =SUM(D26:O26) -> -18000 | R26: =Operational!R12 -> -3168 | S26: =Operational!S12 -> -3168 | T26: =Operational!T12 -> -3168 | U26: =Operational!U12 -> -3168 | V26: =Operational!V12 -> -3168 | W26: =Operational!W12 -> -3168 | X26: =Operational!X12 -> -3168 | Y26: =Operational!Y12 -> -3168 | ... AC26: =Operational!AC12 -> -3168 | AD26: =SUM(R26:AC26) -> -38016 | AF26: =Operational!AF12 -> -3329.568 | AG26: =Operational!AG12 -> -3329.568 | AH26: =Operational!AH12 -> -3329.568 | AI26: =Operational!AI12 -> -3329.568 | AJ26: =Operational!AJ12 -> -3329.568 | AK26: =Operational!AK12 -> -3329.568 | AL26: =Operational!AL12 -> -3329.568 | AM26: =Operational!AM12 -> -3329.568 | ... AQ26: =Operational!AQ12 -> -3329.568 | AR26: =SUM(AF26:AQ26) -> -39954.816 | AT26: =Operational!AT12 -> -3499.376 | AU26: =Operational!AU12 -> -3499.376 | AV26: =Operational!AV12 -> -3499.376 | AW26: =Operational!AW12 -> -3499.376 | AX26: =Operational!AX12 -> -3499.376 | AY26: =Operational!AY12 -> -3499.376 | AZ26: =Operational!AZ12 -> -3499.376 | BA26: =Operational!BA12 -> -3499.376 | ... BE26: =Operational!BE12 -> -3499.376 | BF26: =SUM(AT26:BE26) -> -41992.512 | BH26: =Operational!BH12 -> -3677.8441 | BI26: =Operational!BI12 -> -3677.8441 | BJ26: =Operational!BJ12 -> -3677.8441 | BK26: =Operational!BK12 -> -3677.8441 | BL26: =Operational!BL12 -> -3677.8441 | BM26: =Operational!BM12 -> -3677.8441 | BN26: =Operational!BN12 -> -3677.8441 | BO26: =Operational!BO12 -> -3677.8441 | ... BS26: =Operational!BS12 -> -3677.8441 | BT26: =SUM(BH26:BS26) -> -44134.13 | BV26: =Operational!BV12 -> -3865.4142 | BW26: =Operational!BW12 -> -3865.4142 | BX26: =Operational!BX12 -> -3865.4142 | BY26: =Operational!BY12 -> -3865.4142 | BZ26: =Operational!BZ12 -> -3865.4142 | CA26: =Operational!CA12 -> -3865.4142 | CB26: =Operational!CB12 -> -3865.4142 | CC26: =Operational!CC12 -> -3865.4142 | ... CG26: =Operational!CG12 -> -3865.4142 | CH26: =SUM(BV26:CG26) -> -46384.97
B27: =Operational!B13 -> Storage | C27: =Operational!C13 -> 02a | D27: =Operational!D13 -> 0 | E27: =Operational!E13 -> 0 | F27: =Operational!F13 -> 0 | G27: =Operational!G13 -> 0 | H27: =Operational!H13 -> 0 | I27: =Operational!I13 -> 0 | ... O27: =Operational!O13 -> 0 | P27: =SUM(D27:O27) -> 0 | R27: =Operational!R13 -> 0 | S27: =Operational!S13 -> 0 | T27: =Operational!T13 -> 0 | U27: =Operational!U13 -> 0 | V27: =Operational!V13 -> 0 | W27: =Operational!W13 -> 0 | X27: =Operational!X13 -> 0 | Y27: =Operational!Y13 -> 0 | ... AC27: =Operational!AC13 -> 0 | AD27: =SUM(R27:AC27) -> 0 | AF27: =Operational!AF13 -> 0 | AG27: =Operational!AG13 -> 0 | AH27: =Operational!AH13 -> 0 | AI27: =Operational!AI13 -> 0 | AJ27: =Operational!AJ13 -> 0 | AK27: =Operational!AK13 -> 0 | AL27: =Operational!AL13 -> 0 | AM27: =Operational!AM13 -> 0 | ... AQ27: =Operational!AQ13 -> 0 | AR27: =SUM(AF27:AQ27) -> 0 | AT27: =Operational!AT13 -> 0 | AU27: =Operational!AU13 -> 0 | AV27: =Operational!AV13 -> 0 | AW27: =Operational!AW13 -> 0 | AX27: =Operational!AX13 -> 0 | AY27: =Operational!AY13 -> 0 | AZ27: =Operational!AZ13 -> 0 | BA27: =Operational!BA13 -> 0 | ... BE27: =Operational!BE13 -> 0 | BF27: =SUM(AT27:BE27) -> 0 | BH27: =Operational!BH13 -> 0 | BI27: =Operational!BI13 -> 0 | BJ27: =Operational!BJ13 -> 0 | BK27: =Operational!BK13 -> 0 | BL27: =Operational!BL13 -> 0 | BM27: =Operational!BM13 -> 0 | BN27: =Operational!BN13 -> 0 | BO27: =Operational!BO13 -> 0 | ... BS27: =Operational!BS13 -> 0 | BT27: =SUM(BH27:BS27) -> 0 | BV27: =Operational!BV13 -> 0 | BW27: =Operational!BW13 -> 0 | BX27: =Operational!BX13 -> 0 | BY27: =Operational!BY13 -> 0 | BZ27: =Operational!BZ13 -> 0 | CA27: =Operational!CA13 -> 0 | CB27: =Operational!CB13 -> 0 | CC27: =Operational!CC13 -> 0 | ... CG27: =Operational!CG13 -> 0 | CH27: =SUM(BV27:CG27) -> 0
B28: =Operational!B14 -> x | C28: =Operational!C14 -> O2b | D28: =Operational!D14 -> 0 | E28: =Operational!E14 -> 0 | F28: =Operational!F14 -> 0 | G28: =Operational!G14 -> 0 | H28: =Operational!H14 -> 0 | I28: =Operational!I14 -> 0 | ... O28: =Operational!O14 -> 0 | P28: =SUM(D28:O28) -> 0 | R28: =Operational!R14 -> 0 | S28: =Operational!S14 -> 0 | T28: =Operational!T14 -> 0 | U28: =Operational!U14 -> 0 | V28: =Operational!V14 -> 0 | W28: =Operational!W14 -> 0 | X28: =Operational!X14 -> 0 | Y28: =Operational!Y14 -> 0 | ... AC28: =Operational!AC14 -> 0 | AD28: =SUM(R28:AC28) -> 0 | AF28: =Operational!AF14 -> 0 | AG28: =Operational!AG14 -> 0 | AH28: =Operational!AH14 -> 0 | AI28: =Operational!AI14 -> 0 | AJ28: =Operational!AJ14 -> 0 | AK28: =Operational!AK14 -> 0 | AL28: =Operational!AL14 -> 0 | AM28: =Operational!AM14 -> 0 | ... AQ28: =Operational!AQ14 -> 0 | AR28: =SUM(AF28:AQ28) -> 0 | AT28: =Operational!AT14 -> 0 | AU28: =Operational!AU14 -> 0 | AV28: =Operational!AV14 -> 0 | AW28: =Operational!AW14 -> 0 | AX28: =Operational!AX14 -> 0 | AY28: =Operational!AY14 -> 0 | AZ28: =Operational!AZ14 -> 0 | BA28: =Operational!BA14 -> 0 | ... BE28: =Operational!BE14 -> 0 | BF28: =SUM(AT28:BE28) -> 0 | BH28: =Operational!BH14 -> 0 | BI28: =Operational!BI14 -> 0 | BJ28: =Operational!BJ14 -> 0 | BK28: =Operational!BK14 -> 0 | BL28: =Operational!BL14 -> 0 | BM28: =Operational!BM14 -> 0 | BN28: =Operational!BN14 -> 0 | BO28: =Operational!BO14 -> 0 | ... BS28: =Operational!BS14 -> 0 | BT28: =SUM(BH28:BS28) -> 0 | BV28: =Operational!BV14 -> 0 | BW28: =Operational!BW14 -> 0 | BX28: =Operational!BX14 -> 0 | BY28: =Operational!BY14 -> 0 | BZ28: =Operational!BZ14 -> 0 | CA28: =Operational!CA14 -> 0 | CB28: =Operational!CB14 -> 0 | CC28: =Operational!CC14 -> 0 | ... CG28: =Operational!CG14 -> 0 | CH28: =SUM(BV28:CG28) -> 0
B29: =Operational!B15 -> Cleaning | C29: =Operational!C15 -> O3 | D29: =Operational!D15 -> 0 | E29: =Operational!E15 -> 0 | F29: =Operational!F15 -> 0 | G29: =Operational!G15 -> 0 | H29: =Operational!H15 -> 0 | I29: =Operational!I15 -> 0 | ... O29: =Operational!O15 -> -500 | P29: =SUM(D29:O29) -> -3000 | R29: =Operational!R15 -> -528 | S29: =Operational!S15 -> -528 | T29: =Operational!T15 -> -528 | U29: =Operational!U15 -> -528 | V29: =Operational!V15 -> -528 | W29: =Operational!W15 -> -528 | X29: =Operational!X15 -> -528 | Y29: =Operational!Y15 -> -528 | ... AC29: =Operational!AC15 -> -528 | AD29: =SUM(R29:AC29) -> -6336 | AF29: =Operational!AF15 -> -554.928 | AG29: =Operational!AG15 -> -554.928 | AH29: =Operational!AH15 -> -554.928 | AI29: =Operational!AI15 -> -554.928 | AJ29: =Operational!AJ15 -> -554.928 | AK29: =Operational!AK15 -> -554.928 | AL29: =Operational!AL15 -> -554.928 | AM29: =Operational!AM15 -> -554.928 | ... AQ29: =Operational!AQ15 -> -554.928 | AR29: =SUM(AF29:AQ29) -> -6659.136 | AT29: =Operational!AT15 -> -583.22933 | AU29: =Operational!AU15 -> -583.22933 | AV29: =Operational!AV15 -> -583.22933 | AW29: =Operational!AW15 -> -583.22933 | AX29: =Operational!AX15 -> -583.22933 | AY29: =Operational!AY15 -> -583.22933 | AZ29: =Operational!AZ15 -> -583.22933 | BA29: =Operational!BA15 -> -583.22933 | ... BE29: =Operational!BE15 -> -583.22933 | BF29: =SUM(AT29:BE29) -> -6998.7519 | BH29: =Operational!BH15 -> -612.97402 | BI29: =Operational!BI15 -> -612.97402 | BJ29: =Operational!BJ15 -> -612.97402 | BK29: =Operational!BK15 -> -612.97402 | BL29: =Operational!BL15 -> -612.97402 | BM29: =Operational!BM15 -> -612.97402 | BN29: =Operational!BN15 -> -612.97402 | BO29: =Operational!BO15 -> -612.97402 | ... BS29: =Operational!BS15 -> -612.97402 | BT29: =SUM(BH29:BS29) -> -7355.6883 | BV29: =Operational!BV15 -> -644.2357 | BW29: =Operational!BW15 -> -644.2357 | BX29: =Operational!BX15 -> -644.2357 | BY29: =Operational!BY15 -> -644.2357 | BZ29: =Operational!BZ15 -> -644.2357 | CA29: =Operational!CA15 -> -644.2357 | CB29: =Operational!CB15 -> -644.2357 | CC29: =Operational!CC15 -> -644.2357 | ... CG29: =Operational!CG15 -> -644.2357 | CH29: =SUM(BV29:CG29) -> -7730.8284
B30: =Operational!B16 -> Electricity | C30: =Operational!C16 -> O4 | D30: =Operational!D16 -> 0 | E30: =Operational!E16 -> 0 | F30: =Operational!F16 -> 0 | G30: =Operational!G16 -> 0 | H30: =Operational!H16 -> 0 | I30: =Operational!I16 -> 0 | ... O30: =Operational!O16 -> -550 | P30: =SUM(D30:O30) -> -3300 | R30: =Operational!R16 -> -580.8 | S30: =Operational!S16 -> -580.8 | T30: =Operational!T16 -> -580.8 | U30: =Operational!U16 -> -580.8 | V30: =Operational!V16 -> -580.8 | W30: =Operational!W16 -> -580.8 | X30: =Operational!X16 -> -580.8 | Y30: =Operational!Y16 -> -580.8 | ... AC30: =Operational!AC16 -> -580.8 | AD30: =SUM(R30:AC30) -> -6969.6 | AF30: =Operational!AF16 -> -610.4208 | AG30: =Operational!AG16 -> -610.4208 | AH30: =Operational!AH16 -> -610.4208 | AI30: =Operational!AI16 -> -610.4208 | AJ30: =Operational!AJ16 -> -610.4208 | AK30: =Operational!AK16 -> -610.4208 | AL30: =Operational!AL16 -> -610.4208 | AM30: =Operational!AM16 -> -610.4208 | ... AQ30: =Operational!AQ16 -> -610.4208 | AR30: =SUM(AF30:AQ30) -> -7325.0496 | AT30: =Operational!AT16 -> -641.55226 | AU30: =Operational!AU16 -> -641.55226 | AV30: =Operational!AV16 -> -641.55226 | AW30: =Operational!AW16 -> -641.55226 | AX30: =Operational!AX16 -> -641.55226 | AY30: =Operational!AY16 -> -641.55226 | AZ30: =Operational!AZ16 -> -641.55226 | BA30: =Operational!BA16 -> -641.55226 | ... BE30: =Operational!BE16 -> -641.55226 | BF30: =SUM(AT30:BE30) -> -7698.6271 | BH30: =Operational!BH16 -> -674.27143 | BI30: =Operational!BI16 -> -674.27143 | BJ30: =Operational!BJ16 -> -674.27143 | BK30: =Operational!BK16 -> -674.27143 | BL30: =Operational!BL16 -> -674.27143 | BM30: =Operational!BM16 -> -674.27143 | BN30: =Operational!BN16 -> -674.27143 | BO30: =Operational!BO16 -> -674.27143 | ... BS30: =Operational!BS16 -> -674.27143 | BT30: =SUM(BH30:BS30) -> -8091.2571 | BV30: =Operational!BV16 -> -708.65927 | BW30: =Operational!BW16 -> -708.65927 | BX30: =Operational!BX16 -> -708.65927 | BY30: =Operational!BY16 -> -708.65927 | BZ30: =Operational!BZ16 -> -708.65927 | CA30: =Operational!CA16 -> -708.65927 | CB30: =Operational!CB16 -> -708.65927 | CC30: =Operational!CC16 -> -708.65927 | ... CG30: =Operational!CG16 -> -708.65927 | CH30: =SUM(BV30:CG30) -> -8503.9112
B31: =Operational!B17 -> Cooling / Heating | C31: =Operational!C17 -> O5 | D31: =Operational!D17 -> 0 | E31: =Operational!E17 -> 0 | F31: =Operational!F17 -> 0 | G31: =Operational!G17 -> 0 | H31: =Operational!H17 -> 0 | I31: =Operational!I17 -> 0 | ... O31: =Operational!O17 -> -200 | P31: =SUM(D31:O31) -> -1200 | R31: =Operational!R17 -> -211.2 | S31: =Operational!S17 -> -211.2 | T31: =Operational!T17 -> -211.2 | U31: =Operational!U17 -> -211.2 | V31: =Operational!V17 -> -211.2 | W31: =Operational!W17 -> -211.2 | X31: =Operational!X17 -> -211.2 | Y31: =Operational!Y17 -> -211.2 | ... AC31: =Operational!AC17 -> -211.2 | AD31: =SUM(R31:AC31) -> -2534.4 | AF31: =Operational!AF17 -> -221.9712 | AG31: =Operational!AG17 -> -221.9712 | AH31: =Operational!AH17 -> -221.9712 | AI31: =Operational!AI17 -> -221.9712 | AJ31: =Operational!AJ17 -> -221.9712 | AK31: =Operational!AK17 -> -221.9712 | AL31: =Operational!AL17 -> -221.9712 | AM31: =Operational!AM17 -> -221.9712 | ... AQ31: =Operational!AQ17 -> -221.9712 | AR31: =SUM(AF31:AQ31) -> -2663.6544 | AT31: =Operational!AT17 -> -233.29173 | AU31: =Operational!AU17 -> -233.29173 | AV31: =Operational!AV17 -> -233.29173 | AW31: =Operational!AW17 -> -233.29173 | AX31: =Operational!AX17 -> -233.29173 | AY31: =Operational!AY17 -> -233.29173 | AZ31: =Operational!AZ17 -> -233.29173 | BA31: =Operational!BA17 -> -233.29173 | ... BE31: =Operational!BE17 -> -233.29173 | BF31: =SUM(AT31:BE31) -> -2799.5008 | BH31: =Operational!BH17 -> -245.18961 | BI31: =Operational!BI17 -> -245.18961 | BJ31: =Operational!BJ17 -> -245.18961 | BK31: =Operational!BK17 -> -245.18961 | BL31: =Operational!BL17 -> -245.18961 | BM31: =Operational!BM17 -> -245.18961 | BN31: =Operational!BN17 -> -245.18961 | BO31: =Operational!BO17 -> -245.18961 | ... BS31: =Operational!BS17 -> -245.18961 | BT31: =SUM(BH31:BS31) -> -2942.2753 | BV31: =Operational!BV17 -> -257.69428 | BW31: =Operational!BW17 -> -257.69428 | BX31: =Operational!BX17 -> -257.69428 | BY31: =Operational!BY17 -> -257.69428 | BZ31: =Operational!BZ17 -> -257.69428 | CA31: =Operational!CA17 -> -257.69428 | CB31: =Operational!CB17 -> -257.69428 | CC31: =Operational!CC17 -> -257.69428 | ... CG31: =Operational!CG17 -> -257.69428 | CH31: =SUM(BV31:CG31) -> -3092.3314
B32: =Operational!B18 -> Service Charges | C32: =Operational!C18 -> O6 | D32: =Operational!D18 -> 0 | E32: =Operational!E18 -> 0 | F32: =Operational!F18 -> 0 | G32: =Operational!G18 -> 0 | H32: =Operational!H18 -> 0 | I32: =Operational!I18 -> 0 | ... O32: =Operational!O18 -> -350 | P32: =SUM(D32:O32) -> -2100 | R32: =Operational!R18 -> -369.6 | S32: =Operational!S18 -> -369.6 | T32: =Operational!T18 -> -369.6 | U32: =Operational!U18 -> -369.6 | V32: =Operational!V18 -> -369.6 | W32: =Operational!W18 -> -369.6 | X32: =Operational!X18 -> -369.6 | Y32: =Operational!Y18 -> -369.6 | ... AC32: =Operational!AC18 -> -369.6 | AD32: =SUM(R32:AC32) -> -4435.2 | AF32: =Operational!AF18 -> -388.4496 | AG32: =Operational!AG18 -> -388.4496 | AH32: =Operational!AH18 -> -388.4496 | AI32: =Operational!AI18 -> -388.4496 | AJ32: =Operational!AJ18 -> -388.4496 | AK32: =Operational!AK18 -> -388.4496 | AL32: =Operational!AL18 -> -388.4496 | AM32: =Operational!AM18 -> -388.4496 | ... AQ32: =Operational!AQ18 -> -388.4496 | AR32: =SUM(AF32:AQ32) -> -4661.3952 | AT32: =Operational!AT18 -> -408.26053 | AU32: =Operational!AU18 -> -408.26053 | AV32: =Operational!AV18 -> -408.26053 | AW32: =Operational!AW18 -> -408.26053 | AX32: =Operational!AX18 -> -408.26053 | AY32: =Operational!AY18 -> -408.26053 | AZ32: =Operational!AZ18 -> -408.26053 | BA32: =Operational!BA18 -> -408.26053 | ... BE32: =Operational!BE18 -> -408.26053 | BF32: =SUM(AT32:BE32) -> -4899.1264 | BH32: =Operational!BH18 -> -429.08182 | BI32: =Operational!BI18 -> -429.08182 | BJ32: =Operational!BJ18 -> -429.08182 | BK32: =Operational!BK18 -> -429.08182 | BL32: =Operational!BL18 -> -429.08182 | BM32: =Operational!BM18 -> -429.08182 | BN32: =Operational!BN18 -> -429.08182 | BO32: =Operational!BO18 -> -429.08182 | ... BS32: =Operational!BS18 -> -429.08182 | BT32: =SUM(BH32:BS32) -> -5148.9818 | BV32: =Operational!BV18 -> -450.96499 | BW32: =Operational!BW18 -> -450.96499 | BX32: =Operational!BX18 -> -450.96499 | BY32: =Operational!BY18 -> -450.96499 | BZ32: =Operational!BZ18 -> -450.96499 | CA32: =Operational!CA18 -> -450.96499 | CB32: =Operational!CB18 -> -450.96499 | CC32: =Operational!CC18 -> -450.96499 | ... CG32: =Operational!CG18 -> -450.96499 | CH32: =SUM(BV32:CG32) -> -5411.5799
B33: OPERATIONAL | D33: =SUM(D26:D32) -> 0 | E33: =SUM(E26:E32) -> 0 | F33: =SUM(F26:F32) -> 0 | G33: =SUM(G26:G32) -> 0 | H33: =SUM(H26:H32) -> 0 | I33: =SUM(I26:I32) -> 0 | J33: =SUM(J26:J32) -> -4600 | K33: =SUM(K26:K32) -> -4600 | ... O33: =SUM(O26:O32) -> -4600 | P33: =SUM(D33:O33) -> -27600 | R33: =SUM(R26:R32) -> -4857.6 | S33: =SUM(S26:S32) -> -4857.6 | T33: =SUM(T26:T32) -> -4857.6 | U33: =SUM(U26:U32) -> -4857.6 | V33: =SUM(V26:V32) -> -4857.6 | W33: =SUM(W26:W32) -> -4857.6 | X33: =SUM(X26:X32) -> -4857.6 | Y33: =SUM(Y26:Y32) -> -4857.6 | ... AC33: =SUM(AC26:AC32) -> -4857.6 | AD33: =SUM(R33:AC33) -> -58291.2 | AF33: =SUM(AF26:AF32) -> -5105.3376 | AG33: =SUM(AG26:AG32) -> -5105.3376 | AH33: =SUM(AH26:AH32) -> -5105.3376 | AI33: =SUM(AI26:AI32) -> -5105.3376 | AJ33: =SUM(AJ26:AJ32) -> -5105.3376 | AK33: =SUM(AK26:AK32) -> -5105.3376 | AL33: =SUM(AL26:AL32) -> -5105.3376 | AM33: =SUM(AM26:AM32) -> -5105.3376 | ... AQ33: =SUM(AQ26:AQ32) -> -5105.3376 | AR33: =SUM(AF33:AQ33) -> -61264.051 | AT33: =SUM(AT26:AT32) -> -5365.7098 | AU33: =SUM(AU26:AU32) -> -5365.7098 | AV33: =SUM(AV26:AV32) -> -5365.7098 | AW33: =SUM(AW26:AW32) -> -5365.7098 | AX33: =SUM(AX26:AX32) -> -5365.7098 | AY33: =SUM(AY26:AY32) -> -5365.7098 | AZ33: =SUM(AZ26:AZ32) -> -5365.7098 | BA33: =SUM(BA26:BA32) -> -5365.7098 | ... BE33: =SUM(BE26:BE32) -> -5365.7098 | BF33: =SUM(AT33:BE33) -> -64388.518 | BH33: =SUM(BH26:BH32) -> -5639.361 | BI33: =SUM(BI26:BI32) -> -5639.361 | BJ33: =SUM(BJ26:BJ32) -> -5639.361 | BK33: =SUM(BK26:BK32) -> -5639.361 | BL33: =SUM(BL26:BL32) -> -5639.361 | BM33: =SUM(BM26:BM32) -> -5639.361 | BN33: =SUM(BN26:BN32) -> -5639.361 | BO33: =SUM(BO26:BO32) -> -5639.361 | ... BS33: =SUM(BS26:BS32) -> -5639.361 | BT33: =SUM(BH33:BS33) -> -67672.332 | BV33: =SUM(BV26:BV32) -> -5926.9684 | BW33: =SUM(BW26:BW32) -> -5926.9684 | BX33: =SUM(BX26:BX32) -> -5926.9684 | BY33: =SUM(BY26:BY32) -> -5926.9684 | BZ33: =SUM(BZ26:BZ32) -> -5926.9684 | CA33: =SUM(CA26:CA32) -> -5926.9684 | CB33: =SUM(CB26:CB32) -> -5926.9684 | CC33: =SUM(CC26:CC32) -> -5926.9684 | ... CG33: =SUM(CG26:CG32) -> -5926.9684 | CH33: =SUM(BV33:CG33) -> -71123.621
B35: ='Staff - Costs 2'!B12 -> Managing Director | C35: ='Staff - Costs 2'!C12 -> P1 | D35: ='Staff - Costs 2'!D12 -> 0 | E35: ='Staff - Costs 2'!E12 -> 0 | F35: ='Staff - Costs 2'!F12 -> 0 | G35: ='Staff - Costs 2'!G12 -> 0 | H35: ='Staff - Costs 2'!H12 -> 0 | I35: ='Staff - Costs 2'!I12 -> 0 | ... O35: ='Staff - Costs 2'!O12 -> -7383.096 | P35: =SUM(D35:O35) -> -34454.448 | R35: ='Staff - Costs 2'!R12 -> -5197.6996 | S35: ='Staff - Costs 2'!S12 -> -5197.6996 | T35: ='Staff - Costs 2'!T12 -> -5197.6996 | U35: ='Staff - Costs 2'!U12 -> -5197.6996 | V35: ='Staff - Costs 2'!V12 -> -5197.6996 | W35: ='Staff - Costs 2'!W12 -> -5197.6996 | X35: ='Staff - Costs 2'!X12 -> -5197.6996 | Y35: ='Staff - Costs 2'!Y12 -> -5197.6996 | ... AC35: ='Staff - Costs 2'!AC12 -> -7796.5494 | AD35: =SUM(R35:AC35) -> -67570.095 | AF35: ='Staff - Costs 2'!AF12 -> -5462.7823 | AG35: ='Staff - Costs 2'!AG12 -> -5462.7823 | AH35: ='Staff - Costs 2'!AH12 -> -5462.7823 | AI35: ='Staff - Costs 2'!AI12 -> -5462.7823 | AJ35: ='Staff - Costs 2'!AJ12 -> -5462.7823 | AK35: ='Staff - Costs 2'!AK12 -> -5462.7823 | AL35: ='Staff - Costs 2'!AL12 -> -5462.7823 | AM35: ='Staff - Costs 2'!AM12 -> -5462.7823 | ... AQ35: ='Staff - Costs 2'!AQ12 -> -8194.1734 | AR35: =SUM(AF35:AQ35) -> -71016.169 | AT35: ='Staff - Costs 2'!AT12 -> -5741.3842 | AU35: ='Staff - Costs 2'!AU12 -> -5741.3842 | AV35: ='Staff - Costs 2'!AV12 -> -5741.3842 | AW35: ='Staff - Costs 2'!AW12 -> -5741.3842 | AX35: ='Staff - Costs 2'!AX12 -> -5741.3842 | AY35: ='Staff - Costs 2'!AY12 -> -5741.3842 | AZ35: ='Staff - Costs 2'!AZ12 -> -5741.3842 | BA35: ='Staff - Costs 2'!BA12 -> -5741.3842 | ... BE35: ='Staff - Costs 2'!BE12 -> -8612.0762 | BF35: =SUM(AT35:BE35) -> -74637.994 | BH35: ='Staff - Costs 2'!BH12 -> -6034.1947 | BI35: ='Staff - Costs 2'!BI12 -> -6034.1947 | BJ35: ='Staff - Costs 2'!BJ12 -> -6034.1947 | BK35: ='Staff - Costs 2'!BK12 -> -6034.1947 | BL35: ='Staff - Costs 2'!BL12 -> -6034.1947 | BM35: ='Staff - Costs 2'!BM12 -> -6034.1947 | BN35: ='Staff - Costs 2'!BN12 -> -6034.1947 | BO35: ='Staff - Costs 2'!BO12 -> -6034.1947 | ... BS35: ='Staff - Costs 2'!BS12 -> -9051.2921 | BT35: =SUM(BH35:BS35) -> -78444.532 | BV35: ='Staff - Costs 2'!BV12 -> -6341.9387 | BW35: ='Staff - Costs 2'!BW12 -> -6341.9387 | BX35: ='Staff - Costs 2'!BX12 -> -6341.9387 | BY35: ='Staff - Costs 2'!BY12 -> -6341.9387 | BZ35: ='Staff - Costs 2'!BZ12 -> -6341.9387 | CA35: ='Staff - Costs 2'!CA12 -> -6341.9387 | CB35: ='Staff - Costs 2'!CB12 -> -6341.9387 | CC35: ='Staff - Costs 2'!CC12 -> -6341.9387 | ... CG35: ='Staff - Costs 2'!CG12 -> -9512.908 | CH35: =SUM(BV35:CG35) -> -82445.203
